Workbook

Sheet RESUME
A1: ELECTRO COOL
A2: RESUME FACTURATION 2026 | D2: au | E2: 46053
F6: PRODUITS | M6: TOTAL
B7: CLIM | D7: ASCENSEUR | E7: TVA | F7: Total | I7: SN | K7: Total | M7: FACTURATION
H8: Plomberie | I8: CLIM | J8: ASC
A9: JANVIER | B9: ='FACTURES NORMALISEES'!I53 -> 42114.94 | D9: ='FACTURES NORMALISEES'!H53 -> 18739.23 | E9: ='FACTURES NORMALISEES'!F53+'FACTURES NORMALISEES'!G53 -> 5063.3655 | F9: =+B9+D9+E9 -> 65917.536 | H9: ='FACTURES SN'!F39 -> 0 | I9: ='FACTURES SN'!G39 -> 691 | J9: ='FACTURES SN'!H39 -> 10684.2 | K9: =+H9+I9+J9 -> 11375.2 | M9: =+F9+K9 -> 77292.736
A10: FEVRIER | B10: ='FACTURES NORMALISEES'!I114 -> 141888.13 | D10: ='FACTURES NORMALISEES'!H114 -> 21558.18 | E10: ='FACTURES NORMALISEES'!F114+'FACTURES NORMALISEES'!G114 -> 21908.801 | F10: =+B10+D10+E10 -> 185355.11 | H10: ='FACTURES SN'!F92 -> 0 | I10: ='FACTURES SN'!G92 -> 56900 | J10: ='FACTURES SN'!H92 -> 0 | K10: =+H10+I10+J10 -> 56900 | M10: =+F10+K10 -> 242255.11
A11: MARS | B11: ='FACTURES NORMALISEES'!I191 -> 233055.09 | D11: ='FACTURES NORMALISEES'!E191 -> 218770.45 | E11: ='FACTURES NORMALISEES'!G191 -> 1670.7214 | F11: ='FACTURES NORMALISEES'!H191 -> 15370.23 | H11: ='FACTURES SN'!F93 -> 0 | I11: ='FACTURES SN'!G93 -> 0 | J11: ='FACTURES SN'!H93 -> 367.5 | K11: =+H11+I11+J11 -> 367.5 | M11: =+F11+K11 -> 15737.73
A12: AVRIL | B12: ='FACTURES NORMALISEES'!I235 -> 46656.74 | D12: ='FACTURES NORMALISEES'!E235 -> 49355.534 | E12: ='FACTURES NORMALISEES'!G235 -> 1012.3834 | F12: ='FACTURES NORMALISEES'!H235 -> 9847.28 | H12: ='FACTURES SN'!F94 -> 0 | I12: ='FACTURES SN'!G94 -> 0 | J12: ='FACTURES SN'!H94 -> 183.75 | K12: =+H12+I12+J12 -> 183.75 | M12: =+F12+K12 -> 10031.03
A13: MAI | B13: ='FACTURES NORMALISEES'!I279 -> 41393.22 | D13: ='FACTURES NORMALISEES'!E279 -> 89471.526 | E13: ='FACTURES NORMALISEES'!G279 -> 8164.7241 | F13: ='FACTURES NORMALISEES'!H279 -> 61551.75 | H13: ='FACTURES SN'!F95 -> 0 | I13: ='FACTURES SN'!G95 -> 0 | J13: ='FACTURES SN'!H95 -> 577.5 | K13: =+H13+I13+J13 -> 577.5 | M13: =+F13+K13 -> 62129.25
A14: JUIN | B14: ='FACTURES NORMALISEES'!I339 -> 0 | D14: ='FACTURES NORMALISEES'!E339 -> 0 | E14: ='FACTURES NORMALISEES'!G339 -> 0 | F14: ='FACTURES NORMALISEES'!H339 -> 0 | H14: ='FACTURES SN'!F96 -> 0 | I14: ='FACTURES SN'!G96 -> 0 | J14: ='FACTURES SN'!H96 -> 288.75 | K14: =+H14+I14+J14 -> 288.75 | M14: =+F14+K14 -> 288.75
A15: JUILLET | B15: ='FACTURES NORMALISEES'!I342 -> 0 | D15: ='FACTURES NORMALISEES'!E342 -> 0 | E15: ='FACTURES NORMALISEES'!G342 -> 0 | F15: ='FACTURES NORMALISEES'!H342 -> 0 | H15: ='FACTURES SN'!F97 -> 0 | I15: ='FACTURES SN'!G97 -> 0 | J15: ='FACTURES SN'!H97 -> 420 | K15: =+H15+I15+J15 -> 420 | M15: =+F15+K15 -> 420
A16: AOUT | B16: ='FACTURES NORMALISEES'!I345 -> 0 | D16: ='FACTURES NORMALISEES'!E345 -> 0 | E16: ='FACTURES NORMALISEES'!G345 -> 0 | F16: ='FACTURES NORMALISEES'!H345 -> 0 | H16: ='FACTURES SN'!F98 -> 0 | I16: ='FACTURES SN'!G98 -> 0 | J16: ='FACTURES SN'!H98 -> 420 | K16: =+H16+I16+J16 -> 420 | M16: =+F16+K16 -> 420
A17: SEPTEMBRE | B17: ='FACTURES NORMALISEES'!I348 -> 0 | D17: ='FACTURES NORMALISEES'!E348 -> 0 | E17: ='FACTURES NORMALISEES'!G348 -> 0 | F17: ='FACTURES NORMALISEES'!H348 -> 0 | H17: ='FACTURES SN'!F99 -> 0 | I17: ='FACTURES SN'!G99 -> 6562.5 | J17: ='FACTURES SN'!H99 -> 0 | K17: =+H17+I17+J17 -> 6562.5 | M17: =+F17+K17 -> 6562.5
A18: OCTOBRE | B18: ='FACTURES NORMALISEES'!I351 -> 0 | D18: ='FACTURES NORMALISEES'!E351 -> 0 | E18: ='FACTURES NORMALISEES'!G351 -> 0 | F18: ='FACTURES NORMALISEES'!H351 -> 0 | H18: ='FACTURES SN'!F100 -> 0 | I18: ='FACTURES SN'!G100 -> 0 | J18: ='FACTURES SN'!H100 -> 400 | K18: =+H18+I18+J18 -> 400 | M18: =+F18+K18 -> 400
A19: NOVEMBRE | B19: ='FACTURES NORMALISEES'!I354 -> 0 | D19: ='FACTURES NORMALISEES'!E354 -> 0 | E19: ='FACTURES NORMALISEES'!G354 -> 0 | F19: ='FACTURES NORMALISEES'!H354 -> 0 | H19: ='FACTURES SN'!F101 -> 0 | I19: ='FACTURES SN'!G101 -> 0 | J19: ='FACTURES SN'!H101 -> 400 | K19: =+H19+I19+J19 -> 400 | M19: =+F19+K19 -> 400
A20: DECEMBRE | B20: ='FACTURES NORMALISEES'!I357 -> 0 | D20: ='FACTURES NORMALISEES'!E357 -> 0 | E20: ='FACTURES NORMALISEES'!G357 -> 0 | F20: ='FACTURES NORMALISEES'!H357 -> 0 | H20: ='FACTURES SN'!F102 -> 0 | I20: ='FACTURES SN'!G102 -> 0 | J20: ='FACTURES SN'!H102 -> 600 | K20: =+H20+I20+J20 -> 600 | M20: =+F20+K20 -> 600
B21: =SUM(B9:B20) -> 505108.12 | D21: =SUM(D9:D20) -> 397894.92 | E21: =SUM(E9:E20) -> 37819.996 | F21: =SUM(F9:F20) -> 338041.91 | H21: =SUM(H9:H20) -> 0 | I21: =SUM(I9:I20) -> 64153.5 | J21: =SUM(J9:J20) -> 14341.7 | K21: =SUM(K9:K20) -> 78495.2 | M21: =SUM(M9:M20) -> 416537.11
I24: TOTAL FACT. | J24: Encaissé | M24: A recouvrer
D26: CLIMATISATION | I26: =B21 -> 505108.12 | J26: ='FACTURES NORMALISEES'!#REF! -> #REF! | M26: =I26-J26 -> #REF!
D27: ASCENSEUR | I27: =D21 -> 397894.92 | J27: ='FACTURES NORMALISEES'!#REF! -> #REF! | M27: =I27-J27 -> #REF!
D28: TVA | I28: =E21 -> 37819.996
D29: TOTAL FACTURES NORMALISEES | I29: =SUM(I26:I28) -> 940823.03 | J29: =SUM(J26:J28) -> #REF! | M29: =SUM(M26:M28) -> #REF!
D31: SN | I31: =K21 -> 78495.2 | J31: ='FACTURES SN'!J263 -> 18450 | M31: =+I31-J31 -> 60045.2
D33: TOTAL | I33: =+I29+I31 -> 1019318.2 | J33: =+J29+J31 -> #REF! | M33: =+M29+M31 -> #REF!

Sheet SUIVI TVA
A1: ELECTROCOOL SARL
A2: SUIVI TVA 2026
E3: PRODUITS | G3: ENCAISSEMENTS | I3: FACTURES | J3: TVA RECOLTEE | N3: TVA CDF | O3: TAXABLE | P3: EXONERE
C4: N / Facture | D4: FACT.Normalisée | E4: ASCENSEUR | F4: CLIM | G4: ASC | H4: CLIM | I4: EXONEREES | J4: A PAYER | K4: PAYE
B6: IMMEUBLE DELPHIN | C6: 2026/DA/01/1 | D6: 136/1-1/2026 | E6: ='FACTURES NORMALISEES'!E6 -> 200 | G6: 232 | J6: =G6-E6 -> 32 | K6: 32 | N6: 68452.57 | O6: 427828.59
B7: C.H.MONKOLE | C7: 2026/DA/01/2 | D7: 136/1-2/2026 | E7: ='FACTURES NORMALISEES'!E7 -> 700 | I7: 700 | P7: 1497380
B8: AMBABEL | C8: 2026/DA/01/3 | D8: 136/1-3/2026 | E8: ='FACTURES NORMALISEES'!E8 -> 750 | I8: 750 | P8: 1604346
B9: Ambassade BRITANNIQUE | C9: 2026/DA/01/4 | D9: 136/1-4/2026 | E9: ='FACTURES NORMALISEES'!E9 -> 150 | I9: 150 | P9: 320868.32
B10: BANQUE MONDIALE | C10: 2026/DA/01/5 | D10: 136/1-5/2026 | E10: ='FACTURES NORMALISEES'!E10 -> 400 | I10: 400 | P10: 855651.52
B11: IMMEUBLE SERKAS | C11: 2026/DA/01/6 | D11: 136/1-6/2026 | E11: ='FACTURES NORMALISEES'!E11 -> 172.80172 | G11: 200.45 | J11: =G11-E11 -> 27.648276 | K11: 27.65 | N11: 60467.9 | O11: 377924.35
B12: COMMUNAUTE HELENIQUE | C12: 2026/DA/01/7 | D12: 136/1-7/2026 | E12: ='FACTURES NORMALISEES'!E12 -> 120 | G12: 139.2 | J12: =G12-E12 -> 19.2 | K12: 19.2 | N12: 41991.18 | O12: 262444.84
B13: EBALE RESIDENCE | C13: 2026/DA/01/8 | D13: 136/1-8/2026 | E13: ='FACTURES NORMALISEES'!E13 -> 166.25
B14: SOGIC - BOULEVARD | C14: 2026/DA/01/9 | D14: 136/1-9/2026 | E14: ='FACTURES NORMALISEES'!E14 -> 183 | G14: 212.28 | J14: =G14-E14 -> 29.28 | K14: 29.28 | N14: 64036.54 | O14: 400228.4
B15: AFRICANA PALACE | C15: 2026/DA/01/10 | D15: 136/1-10/2026 | E15: ='FACTURES NORMALISEES'!E15 -> 180 | G15: 208.8 | J15: 28.8 | K15: 28.8 | N15: 62986.76 | O15: 393667.28
B16: LFRD | C16: 2026/DA/01/11 | D16: 136/1-11/2026 | E16: ='FACTURES NORMALISEES'!E16 -> 500 | G16: 500 | I16: 500 | P16: 1093520.2
B17: SOGIC | C17: 2026/DA/01/12 | D17: 136/1-12/2026 | E17: ='FACTURES NORMALISEES'!E17 -> 183 | G17: 212.28 | J17: =G17-E17 -> 29.28 | K17: 29.28 | N17: 64036.54 | O17: 400228.4
B18: IMMEUBLE IMANI | C18: 2026/DA/01/13 | D18: 136/1-13/2026 | E18: ='FACTURES NORMALISEES'!E18 -> 200 | G18: 232 | J18: =G18-E18 -> 32 | K18: 32 | N18: 69985.29 | O18: 437408.08
B19: TMB / DG | C19: 2026/DA/01/18 | D19: 136/1-23/2026 | E19: ='FACTURES NORMALISEES'!E28 -> 1327.5 | G19: 212.4 | J19: 212.4 | K19: 212.4 | N19: 467213.24 | O19: 2920082.8
B20: UNICEF | C20: 2026/DT/01/2 | D20: 136/1-26/2026 | F20: ='FACTURES NORMALISEES'!E31 -> 13000 | I20: 13000 | P20: 29077912
B21: LFRD | C21: 2026/DT/01/10 | D21: 136/1-28/2026 | F21: ='FACTURES NORMALISEES'!E33 -> 2940 | I21: 2940 | P21: 6576081.8
B22: C.H.MONKOLE | C22: 2026/DA/01/20 | D22: 136/1-31/2026 | E22: ='FACTURES NORMALISEES'!E36 -> 4000 | G22: 4000 | I22: 4000 | P22: 8947050
B23: US EMBASSY | C23: 2026/DA/01/21 | D23: 136/1-32/2026 | E23: ='FACTURES NORMALISEES'!E37 -> 674.45 | I23: 674.45 | P23: 1508584.5
B24: C.H. MONKOLE | C24: 2026/DA/01/19 | D24: 136/1-33/2026 | E24: ='FACTURES NORMALISEES'!E38 -> 780.32 | G24: 780.32 | I24: 780.32 | P24: 1745390.5
B25: US EMBASSY | C25: 2026/DA/01/22 | D25: 136/1-34/2026 | E25: ='FACTURES NORMALISEES'!E39 -> 250 | I25: 250 | P25: 559190.62
B27: 46023 | E27: =SUM(E5:E26) -> 10937.322 | F27: =SUM(F5:F26) -> 15940 | G27: =SUM(G5:G26) -> 6929.73 | H27: =SUM(H5:H26) -> 0 | I27: =SUM(I5:I26) -> 24144.77 | J27: =SUM(J5:J26) -> 410.60828 | K27: =SUM(K5:K26) -> 410.61 | N27: =SUM(N5:N26) -> 899170.02 | O27: =SUM(O5:O26) -> 5619812.7 | P27: =SUM(P5:P26) -> 53785976
B29: TMB / VICTOIRE | C29: 2026/DA/01/32 | D29: 136/1-44/2026 | E29: ='FACTURES NORMALISEES'!E49 -> 225 | G29: 261 | J29: 36 | K29: 36 | N29: 80523.45 | O29: 583795.01
B30: MAJESTIC RIVER | C30: 2026/DT/01/9 | D30: 136/1-27/2026 | F30: ='FACTURES NORMALISEES'!E32 -> 178 | H30: ='FACTURES NORMALISEES'!#REF! -> #REF! | J30: =H30-F30 -> #REF! | K30: 28.48 | N30: 63703 | O30: 398143.72
B31: MAJESTIC RIVER | C31: 2026/DA/01/26 | D31: 136/1-38/2026 | E31: ='FACTURES NORMALISEES'!E43 -> 350 | G31: 406 | J31: =G31-E31 -> 56 | K31: 56 | N31: 125258.7 | O31: 782866.87
B32: MAJESTIC RIVER | C32: 2026/DA/01/27 | D32: 136/1-39/2026 | E32: ='FACTURES NORMALISEES'!E44 -> 350 | G32: 406 | J32: =G32-E32 -> 56 | K32: 56 | N32: 125258.7 | O32: 782866.87
B33: CONNEXAFRICA | C33: 2026/DT/01/11 | D33: 136/1-29/2026 | F33: ='FACTURES NORMALISEES'!E34 -> 2574 | H33: 2985.84 | J33: ='FACTURES NORMALISEES'!F34 -> 411.84 | K33: 411.84 | N33: 921188.27 | O33: 5757426.7
B34: DEVIMCO | C34: 2026/DA/01/24 | D34: 136/1-35/2026 | E34: ='FACTURES NORMALISEES'!E40 -> 130 | G34: 150.8 | J34: ='FACTURES NORMALISEES'!G40 -> 20.8 | K34: 20.8 | N34: 46524.66 | O34: 290779.12
B35: DEVIMCO | C35: 2026/DA/01/29 | D35: 136/1-40/2026 | E35: ='FACTURES NORMALISEES'!E45 -> 100 | G35: ='FACTURES NORMALISEES'!#REF! -> #REF! | J35: ='FACTURES NORMALISEES'!G45 -> 16 | K35: 16 | N35: 35788.2 | O35: 223676.25
B36: DEVIMCO | C36: 2026/DA/01/30 | D36: 136/1-42/2026 | E36: ='FACTURES NORMALISEES'!E47 -> 240 | G36: ='FACTURES NORMALISEES'!#REF! -> #REF! | J36: ='FACTURES NORMALISEES'!G47 -> 38.4 | K36: 38.4 | N36: 85891.68 | O36: 536823
B37: DEVIMCO | C37: 2026/DA/01/31 | D37: 136/1-43/2026 | E37: ='FACTURES NORMALISEES'!E48 -> 400 | G37: ='FACTURES NORMALISEES'!#REF! -> #REF! | J37: ='FACTURES NORMALISEES'!G48 -> 64 | K37: 64 | N37: 143152.8 | O37: 894705
B38: BELTEXCO | C38: 2026/DA/01/33 | D38: 136/1-45/2026 | E38: ='FACTURES NORMALISEES'!E50 -> 129.5 | G38: ='FACTURES NORMALISEES'!#REF! -> #REF! | J38: ='FACTURES NORMALISEES'!G50 -> 20.72 | K38: 20.72 | N38: 46345.72 | O38: 289660.74
B39: BELTEXCO | C39: 2026/DA/01/34 | D39: 136/1-46/2026 | E39: ='FACTURES NORMALISEES'!E51 -> 147 | G39: ='FACTURES NORMALISEES'!#REF! -> #REF! | J39: ='FACTURES NORMALISEES'!G51 -> 23.52 | K39: 23.52 | N39: 52608.65 | O39: 328804.09
B40: COMMUNAUTE HELLENIQUE | C40: 2026.01/DA/46 | D40: 136/1-63/2026 | E40: ='FACTURES NORMALISEES'!E71 -> 126 | G40: ='FACTURES NORMALISEES'!#REF! -> #REF! | J40: ='FACTURES NORMALISEES'!G71 -> 20.16 | K40: 20.16 | N40: 45260.13 | O40: 282875.82
B41: LFRD | C41: 2026.01/DA/50 | D41: 136/1-67/2026 | E41: =+H41/1.16 -> 0 | G41: 500 | I41: ='FACTURES NORMALISEES'!H75 -> 500 | P41: 1136451.1
B42: C.H. MONKOLE | C42: 2026.01/DA/51 | D42: 136/1-68/2026 | E42: =+H42/1.16 -> 0 | I42: ='FACTURES NORMALISEES'!H76 -> 700 | P42: 1591031.6
B43: US EMBASSY | C43: 2026.01/DA/52 | D43: 136/1-69/2026 | E43: =+H43/1.16 -> 0 | I43: ='FACTURES NORMALISEES'!H77 -> 250 | P43: 568225.57
...

Sheet FACTURES NORMALISEES
A1: ELECTROCOOL SARL
A2: SUIVI FACTURES NORMALISEES - 2026
F3: TVA | H3: FACTURES
A4: DATE | B4: Clients | C4: N / Facture | D4: FACT.Normalisée | E4: PRODUITS | F4: CLIM | G4: ASC | H4: ASCENSEUR | I4: CLIM
A6: 46042 | B6: IMMEUBLE DELPHIN - Redevance 12/2025 | C6: 2026/DA/01/4 | D6: 136/1-1/2026 | E6: =+(H6+I6)/1.16 -> 200 | G6: =+H6-E6 -> 32 | H6: 232
A7: 46042 | B7: C.H.MONKOLE - Redevance 12/2025 | C7: 2026/DA/01/3 | D7: 136/1-2/2026 | E7: 700 | F7: 0 | G7: =+H7-E7 -> 0 | H7: 700
A8: 46042 | B8: AMBABEL - Redevance 12/2025 | C8: 2026/DA/01/1 | D8: 136/1-3/2026 | E8: 750 | F8: 0 | G8: =+H8-E8 -> 0 | H8: 750
A9: 46042 | B9: Ambassade BRITANNIQUE - Redevance 12/2025 | C9: 2026/DA/01/2 | D9: 136/1-4/2026 | E9: 150 | F9: 0 | G9: =+H9-E9 -> 0 | H9: 150
A10: 46042 | B10: BANQUE MONDIALE - Redevance 12/2025 | C10: 2026/DA/01/5 | D10: 136/1-5/2026 | E10: 400 | F10: 0 | G10: =+H10-E10 -> 0 | H10: 400
A11: 46042 | B11: IMMEUBLE SERKAS - Redevance 12/2025 | C11: 2026/DA/01/6 | D11: 136/1-6/2026 | E11: =+(H11+I11)/1.16 -> 172.80172 | G11: =+H11-E11 -> 27.648276 | H11: 200.45
A12: 46042 | B12: COMMUNAUTE HELENIQUE - Redevance 12/2025 | C12: 2026/DA/01/7 | D12: 136/1-7/2026 | E12: =+(H12+I12)/1.16 -> 120 | G12: =+H12-E12 -> 19.2 | H12: 139.2
A13: 46043 | B13: EBALE RESIDENCE - Redevance 12/2025 | C13: 2026/DA/01/8 | D13: 136/1-8/2026 | E13: =+(H13+I13)/1.16 -> 166.25 | G13: =+H13-E13 -> 26.6 | H13: 192.85
A14: 46043 | B14: SOGIC - Redevance BOULEVARD 12/2025 | C14: 2026/DA/01/9 | D14: 136/1-9/2026 | E14: =+(H14+I14)/1.16 -> 183 | G14: =+H14-E14 -> 29.28 | H14: 212.28
A15: 46043 | B15: AFRICANA PALACE - Redevance 12/2025 | C15: 2026/DA/01/10 | D15: 136/1-10/2026 | E15: =+(H15+I15)/1.16 -> 180 | G15: =+H15-E15 -> 28.8 | H15: 208.8
A16: 46043 | B16: LFRD - Redevance 12/2025 | C16: 2026/DA/01/11 | D16: 136/1-11/2026 | E16: 500 | F16: 0 | G16: =+H16-E16 -> 0 | H16: 500
A17: 46043 | B17: SOGIC - Redevance ROI BAUDOUIN 12/2025 | C17: 2026/DA/01/12 | D17: 136/1-12/2026 | E17: =+(H17+I17)/1.16 -> 183 | G17: =+H17-E17 -> 29.28 | H17: 212.28
A18: 46043 | B18: IMMEUBLE IMANI - Redevance 12/2025 | C18: 2026/DA/01/13 | D18: 136/1-13/2026 | E18: =+(H18+I18)/1.16 -> 200 | G18: =+H18-E18 -> 32 | H18: 232
A19: 46044 | B19: EBCDC - Revance escalators 12/2025 | C19: 2026/DA/01/14 | D19: 136/1-14/2026 | E19: =+(H19+I19)/1.16 -> 150 | G19: =+H19-E19 -> 24 | H19: 174
A20: 46044 | B20: UTEXAFRICA - Redevance BOIS NOBLES 2B 12/2025 (522€) | C20: 2026/DA/01/15 | D20: 136/1-15/2026 | E20: =+(H20+I20)/1.16 -> 527.37931 | G20: =+H20-E20 -> 84.38069 | H20: 611.76
A21: 46045 | B21: EXCELLERATE - Entretien 4eTRIM2025 - | C21: 2026/DT/01/1 | D21: 136/1-16/2026 | E21: =+(H21+I21)/1.16 -> 2575 | F21: =+I21-E21 -> 412 | I21: 2987
A22: 46045 | B22: AGL - Fo&po split 12000btu Bureau KINGABWA | C22: 2026/DT/01/3 | D22: 136/1-17/2026 | E22: =+(H22+I22)/1.16 -> 850 | F22: =+I22-E22 -> 136 | I22: 986
A23: 46045 | B23: AGL - Fo&po split 24000btu VILLA 150 UTEX (ANNULEE DUPPLICATA cfr 19/2026) | D23: 136/1-18/2026 | E23: =+(H23+I23)/1.16 -> 0 | F23: =+I23-E23 -> 0 | G23: =+H23-E23 -> 0
A24: 46045 | B24: AGL - Fo&po split 24000btu VILLA 150 UTEX | C24: 2026/DT/01/4 | D24: 136/1-19/2026 | E24: =+(H24+I24)/1.16 -> 1150 | F24: =+I24-E24 -> 184 | I24: 1334
A25: 46045 | B25: TCK - Entretien 12/2025 | C25: 2026/DT/01/5 | D25: 136/1-20/2026 | E25: =+(H25+I25)/1.16 -> 384 | F25: =+I25-E25 -> 61.44 | I25: 445.44
A26: 46045 | B26: SILIKIN VILLAGE - Entretien clim 12/2025 (ANNULEE cfr COTEX 138/2026 ) | C26: 2026/DT/01/6 | D26: 136/1-21/2026 | E26: =+(H26+I26)/1.16 -> 0 | F26: =+I26-E26 -> 0 | I26: =7609.6-7609.6 -> 0
A27: 46045 | B27: EBCDC/IAG - Redevance CONCESSION 12/2025 | C27: 2026/DA/01/17 | D27: 136/1-22/2026 | E27: =+(H27+I27)/1.16 -> 1200 | G27: =+H27-E27 -> 192 | H27: 1392
A28: 46045 | B28: TMB - Redevance SIEGE 12/2025 | C28: 2026/DA/01/18 | D28: 136/1-23/2026 | E28: =+(H28+I28)/1.16 -> 1327.5 | G28: =+H28-E28 -> 212.4 | H28: 1539.9
A29: 46050 | B29: LPL - Entretien clim 1erQUAD2026 | C29: 2026/DT/01/7 | D29: 136/1-24/2026 | E29: =+(H29+I29)/1.16 -> 2250 | F29: =+I29-E29 -> 360 | I29: 2610
A30: 46050 | B30: RAWBANK SARL - Entretien clim 1eTRIM.2026 (corrigé 4eTRIM.2025) | C30: 2026/DT/01/8 | D30: 136/1-25/2026 | E30: =+(H30+I30)/1.16 -> 12603.603 | F30: =+I30-E30 -> 2016.5766 | I30: 14620.18
A31: 46050 | B31: UNICEF - Maintenance HUB/KINKOLE 12/2025 | C31: 2026/DT/01/2 | D31: 136/1-26/2026 | E31: 13000 | F31: =+I31-E31 -> 0 | G31: 0 | I31: 13000
A32: 46050 | B32: MAJESTIC RIVER - Depannage CF 12/2025 | C32: 2026/DT/01/9 | D32: 136/1-27/2026 | E32: =+(H32+I32)/1.16 -> 178 | F32: =+I32-E32 -> 28.48 | I32: 206.48
A33: 46050 | B33: LFRD - Entretien clim 1erTRIM.2026 | C33: 2026/DT/01/10 | D33: 136/1-28/2026 | E33: 2940 | F33: =+I33-E33 -> 0 | G33: 0 | I33: 2940
A34: 46050 | B34: CONNEXAFRICA RDC - Entretien clim 1erTRIM.2026 | C34: 2026/DT/01/11 | D34: 136/1-29/2026 | E34: =+(H34+I34)/1.16 -> 2574 | F34: =+I34-E34 -> 411.84 | I34: 2985.84
A35: 46050 | B35: EBCDC - Redevance semestrielle ESCALATORS | C35: 2026/DA/01/16 | D35: 136/1-30/2026 | E35: =+(H35+I35)/1.16 -> 1600 | G35: =+H35-E35 -> 256 | H35: 1856
A36: 46050 | B36: C.H. MONKOLE - Fo&po 3 courroies de traction | C36: 2026/DA/01/20 | D36: 136/1-31/2026 | E36: 4000 | F36: 0 | G36: =+H36-E36 -> 0 | H36: 4000
A37: 46050 | B37: US EMBASSY - Fo&po 3 Remote ASC | C37: 2026/DA/01/21 | D37: 136/1-32/2026 | E37: 674.45 | F37: 0 | G37: =+H37-E37 -> 0 | H37: 674.45
A38: 46050 | B38: C.H. MONKOLE - Fo&po 4 Galets porte cabine | C38: 2026/DA/01/19 | D38: 136/1-33/2026 | E38: 780.32 | F38: 0 | G38: =+H38-E38 -> 0 | H38: 780.32
A39: 46050 | B39: US EMBASSY - Redevance 122025 - 2026.01/DA/22 | C39: 2026/DA/01/22 | D39: 136/1-34/2026 | E39: 250 | F39: 0 | G39: =+H39-E39 -> 0 | H39: 250
A40: 46050 | B40: DEVIMCO / PRESTIGE - Redevance 122025 - 2026.01/DA/24 | C40: 2026/DA/01/24 | D40: 136/1-35/2026 | E40: =+H40/1.16 -> 130 | G40: =+H40-E40 -> 20.8 | H40: 150.8
A41: 46050 | B41: WAGENIA - Redevance 122025 - 2026.01/DA/23 | C41: 2026/DA/01/23 | D41: 136/1-36/2026 | E41: =+H41/1.16 -> 250 | G41: =+H41-E41 -> 40 | H41: 290
...

Sheet FACTURES SN
A1: ELECTROCOOL SARL
A2: FACTURATION SN 2026
A4: DATE | B4: Clients | C4: N° Facture | D4: PRODUITS | E4: TVA | G4: SN | I4: Total | J4: Encaissement | K4: Solde
F5: Plomberie | G5: CLIM | H5: ASC
A7: 46018 | B7: SHEHENAJ L.M. - Fo&po 2 garnitures cabine IMM. MBUJI MAYI (ANNULEE cfr 2025/SN12/1 | C7: 2026.01/SN/1 | D7: =+I7-E7 -> 0 | I7: 0 | K7: =I7-J7 -> 0 | BG7: =AX7+AW7+AV7+AU7+AT7+AS7+AR7+AQ7+AP7+AN7+AM7+AL7+AK7+AJ7+AI7+AH7+AG7+AF7+AE7+AD7+AC7+AB7+AA7+Z7+Y7+X7+W7+V7+U7+T7+S7+R7+Q7+P7+O7+N7+M7 -> 0
A8: 46018 | B8: SHEHENAJ L.M. - Fo&po 1 bouton appel cabine IMM. COMMERCE (ANNULEE cfr 2025/SN12/2 | C8: 2026.01/SN/2 | D8: =+I8-E8 -> 0 | I8: 0 | K8: =I8-J8 -> 0 | BG8: =AX8+AW8+AV8+AU8+AT8+AS8+AR8+AQ8+AP8+AN8+AM8+AL8+AK8+AJ8+AI8+AH8+AG8+AF8+AE8+AD8+AC8+AB8+AA8+Z8+Y8+X8+W8+V8+U8+T8+S8+R8+Q8+P8+O8+N8+M8 -> 0
A9: 46018 | B9: SHEHENAJ L.M. - Redevance IMMEUBLE COMMERCE 12/2025 (ANNULEE cfr 2025/SN12/3) | C9: 2026.01/SN/3 | D9: =+I9-E9 -> 0 | I9: 0 | K9: =I9-J9 -> 0 | BG9: =AX9+AW9+AV9+AU9+AT9+AS9+AR9+AQ9+AP9+AN9+AM9+AL9+AK9+AJ9+AI9+AH9+AG9+AF9+AE9+AD9+AC9+AB9+AA9+Z9+Y9+X9+W9+V9+U9+T9+S9+R9+Q9+P9+O9+N9+M9 -> 0
A10: 46018 | B10: SHEHENAJ L.M. - Redevance IMMEUBLE PACIFIQUE 12/2025 (ANNULEE cfr 2025/SN12/4) | C10: 2026.01/SN/4 | D10: =+I10-E10 -> 0 | I10: 0 | K10: =I10-J10 -> 0 | BG10: =AX10+AW10+AV10+AU10+AT10+AS10+AR10+AQ10+AP10+AN10+AM10+AL10+AK10+AJ10+AI10+AH10+AG10+AF10+AE10+AD10+AC10+AB10+AA10+Z10+Y10+X10+W10+V10+U10+T10+S10+R10+Q10+P10+O10+N10+M10 -> 0
C11: 2026.01/SN/5 | D11: =+I11-E11 -> 0 | I11: 0 | K11: =I11-J11 -> 0
C12: 2026.01/SN/6 | D12: =+I12-E12 -> 0 | I12: 0 | K12: =I12-J12 -> 0
A14: 46036 | B14: RESIDENCE EMERAUDE - Réinstallation liaisons frigo APT 2 cfr 2eNIVEAU | C14: 2026.01/SN/1 | D14: =+I14-E14 -> 296 | G14: 296 | I14: 296 | K14: =I14-J14 -> 296
A15: 46036 | B15: RESIDENCE EMERAUDE - Depannage clim APT 2-4 cfr 2eNIVEAU | C15: 2026.01/SN/2 | D15: =+I15-E15 -> 220 | G15: 220 | I15: 220 | J15: 220 | K15: =I15-J15 -> 0
A16: 46036 | B16: SN ZHENDRE - Frais dédouanement colis AERO/LUANO | C16: 2026.01/SN/3 | D16: =+I16-E16 -> 3800 | H16: 3800 | I16: 3800 | K16: =I16-J16 -> 3800
A17: 46036 | B17: A ONE CONSTRUCTION - Redevance mensuelle PANORAMIQUE 12/2025 | C17: 2026.01/SN/4 | D17: =+I17-E17 -> 400 | H17: 400 | I17: 400 | J17: 400 | K17: =I17-J17 -> 0
A18: 46036 | B18: Monsieur KETELEER PRINCE - Entretien clim 12/202 | C18: 2026.01/SN/5 | D18: =+I18-E18 -> 175 | G18: 175 | I18: 175 | J18: 175 | K18: =I18-J18 -> 0
A19: 46036 | B19: LYS SARL - Redevance LYS TOWER 12/2025 | C19: 2026.01/SN/6 | D19: =+I19-E19 -> 200 | H19: 200 | I19: 200 | J19: 200 | K19: =I19-J19 -> 0
A20: 46036 | B20: IMMEUBLE MARIE YVETTE - Redevance mensuelle 12/2025 | C20: 2026.01/SN/7 | D20: =+I20-E20 -> 174 | H20: 174 | I20: 174 | J20: 174 | K20: =I20-J20 -> 0 | BG20: =AX20+AW20+AV20+AU20+AT20+AS20+AR20+AQ20+AP20+AN20+AM20+AL20+AK20+AJ20+AI20+AH20+AG20+AF20+AE20+AD20+AC20+AB20+AA20+Z20+Y20+X20+W20+V20+U20+T20+S20+R20+Q20+P20+O20+N20+M20 -> 0
A21: 46036 | B21: LYS SARL - Redevance LYS CENTER 11/2025 | C21: 2026.01/SN/8 | D21: =+I21-E21 -> 600 | H21: 600 | I21: 600 | J21: 600 | K21: =I21-J21 -> 0 | BG21: =AX21+AW21+AV21+AU21+AT21+AS21+AR21+AQ21+AP21+AN21+AM21+AL21+AK21+AJ21+AI21+AH21+AG21+AF21+AE21+AD21+AC21+AB21+AA21+Z21+Y21+X21+W21+V21+U21+T21+S21+R21+Q21+P21+O21+N21+M21 -> 0
A22: 46036 | B22: IMMEUBLE LEGREY - Redevance mensuelle 12/2025 | C22: 2026.01/SN/9 | D22: =+I22-E22 -> 400 | H22: 400 | I22: 400 | J22: 400 | K22: =I22-J22 -> 0 | BG22: =AX22+AW22+AV22+AU22+AT22+AS22+AR22+AQ22+AP22+AN22+AM22+AL22+AK22+AJ22+AI22+AH22+AG22+AF22+AE22+AD22+AC22+AB22+AA22+Z22+Y22+X22+W22+V22+U22+T22+S22+R22+Q22+P22+O22+N22+M22 -> 0
A23: 46036 | B23: ESPACE SHADARY - Redevance CITE VERTE 12/2025 | C23: 2026.01/SN/10 | D23: =+I23-E23 -> 200 | H23: 200 | I23: 200 | J23: 200 | K23: =I23-J23 -> 0 | BG23: =AX23+AW23+AV23+AU23+AT23+AS23+AR23+AQ23+AP23+AN23+AM23+AL23+AK23+AJ23+AI23+AH23+AG23+AF23+AE23+AD23+AC23+AB23+AA23+Z23+Y23+X23+W23+V23+U23+T23+S23+R23+Q23+P23+O23+N23+M23 -> 0
A24: 46047 | B24: LIBERTY - Redevance mensuelle LUBUMBASHI 01/2026 | C24: 2026.01/SN/11 | D24: =+I24-E24 -> 577.5 | H24: 577.5 | I24: 577.5 | K24: =I24-J24 -> 577.5
A25: 46047 | B25: DEV GROUP - Redevance mensuelle DEV SOLAIRE LUSHI 01/2026 | C25: 2026.01/SN/12 | D25: =+I25-E25 -> 288.75 | H25: 288.75 | I25: 288.75 | J25: 14 | K25: =I25-J25 -> 274.75
A26: 46047 | B26: IMMEUBLE MALAIKA - Redevance 1er TRIM.2026 | C26: 2026.01/SN/13 | D26: =+I26-E26 -> 450 | H26: 450 | I26: 450 | J26: 450 | K26: =I26-J26 -> 0
A27: 46047 | B27: IMMEUBLE MARIE YVETTE - Redevance mensuelle 01/2026 | C27: 2026.01/SN/14 | D27: =+I27-E27 -> 182.7 | H27: 182.7 | I27: 182.7 | J27: 182.7 | K27: =I27-J27 -> 0
A28: 46050 | B28: ESPACE SHADARY - Redevance CITE VERTE 01/2026 | C28: 2026.01/SN/15 | D28: =+I28-E28 -> 210 | H28: 210 | I28: 210 | J28: 210 | K28: =I28-J28 -> 0
A29: 46050 | B29: ESPACE SHADARY - Redevance LUBEFU 01/2026 | C29: 2026.01/SN/16 | D29: =+I29-E29 -> 210 | H29: 210 | I29: 210 | J29: 210 | K29: =I29-J29 -> 0
A30: 46050 | B30: SHEHENAJ L.M. - Redevance COMMERCE (HARMONIE) 01/2026 | C30: 2026.01/SN/17 | D30: =+I30-E30 -> 183.75 | H30: 183.75 | I30: 183.75 | J30: 175 | K30: =I30-J30 -> 8.75
A31: 46050 | B31: SHEHENAJ L.M. - Redevance PACIFIQUE 01/2026 | C31: 2026.01/SN/18 | D31: =+I31-E31 -> 367.5 | H31: 367.5 | I31: 367.5 | J31: 350 | K31: =I31-J31 -> 17.5
A32: 46050 | B32: A ONE CONSTRUCTION - Redevance mensuelle PANORAMIQUE 01/2026 | C32: 2026.01/SN/19 | D32: =+I32-E32 -> 210 | H32: 210 | I32: 210 | J32: 210 | K32: =I32-J32 -> 0
A33: 46050 | B33: IMMEUBLE LEGREY - Redevance mensuelle 01/2026 | C33: 2026.01/SN/20 | D33: =+I33-E33 -> 420 | H33: 420 | I33: 420 | J33: 420 | K33: =I33-J33 -> 0
A34: 46053 | B34: LYS SARL - Redevance LYS CENTER 12/2025 | C34: 2026.01/SN/21 | D34: =+I34-E34 -> 600 | H34: 600 | I34: 600 | J34: 600 | K34: =I34-J34 -> 0
A35: 46053 | B35: LYS SARL - Redevance LYS TOWER 01/2026 | C35: 2026.01/SN/22 | D35: =+I35-E35 -> 400 | H35: 400 | I35: 400 | K35: =I35-J35 -> 400
A36: 46053 | B36: LYS SARL - Redevance LYS CENTER 01/2026 | C36: 2026.01/SN/23 | D36: =+I36-E36 -> 600 | H36: 600 | I36: 600 | J36: 156.4 | K36: =I36-J36 -> 443.6
A37: 46053 | B37: ESPACE SHADARY - Redevance NYEMBO 01/2026 | C37: 2026.01/SN/24 | D37: =+I37-E37 -> 210 | H37: 210 | I37: 210 | K37: =I37-J37 -> 210
BG38: =+AQ38+AP38+AN38+AM38+AL38+AK38+AJ38+AI38+AH38+AG38+AF38+AE38+AD38+AC38+AB38+AA38+Z38+Y38+X38+W38+V38+U38+T38+S38+R38+Q38+P38+O38+N38+M38 -> 0
B39: FACTURATION SN - JANVIER 2026 | D39: =SUM(D7:D38) -> 11375.2 | E39: =SUM(E7:E38) -> 0 | F39: =SUM(F7:F38) -> 0 | G39: =SUM(G7:G38) -> 691 | H39: =SUM(H7:H38) -> 10684.2 | I39: =SUM(I7:I38) -> 11375.2 | J39: =SUM(J7:J38) -> 5347.1 | K39: =I39-J39 -> 6028.1 | M39: =SUM(M7:M38) -> 0 | N39: =SUM(N7:N38) -> 0 | O39: =SUM(O7:O38) -> 0 | P39: =SUM(P7:P38) -> 0 | Q39: =SUM(Q7:Q38) -> 0 | R39: =SUM(R7:R38) -> 0 | S39: =SUM(S7:S38) -> 0 | T39: =SUM(T7:T38) -> 0 | ... AN39: =SUM(AN7:AN38) -> 0 | AP39: =SUM(AP7:AP38) -> 0 | AQ39: =SUM(AQ7:AQ38) -> 0 | AR39: =SUM(AR7:AR38) -> 0 | AS39: =SUM(AS7:AS38) -> 0 | AT39: =SUM(AT7:AT38) -> 0 | AU39: =SUM(AU7:AU38) -> 0 | AV39: =SUM(AV7:AV38) -> 0 | AW39: =SUM(AW7:AW38) -> 0 | ... AY39: =SUM(AY7:AY38) -> 0 | BG39: =SUM(BG7:BG38) -> 0
A41: 46069 | B41: SHEHENAJ L.M. - Redevance PACIFIQUE 02/2026 | C41: 2026.01/SN/25 | D41: =+I41-E41 -> 367.5 | H41: 367.5 | I41: 367.5 | J41: 367.5 | K41: =I41-J41 -> 0
A42: 46069 | B42: A ONE CONSTRUCTION - Redevance PANORAMIQUE (ESTORIL) 02/2026 | C42: 2026.01/SN/26 | D42: =+I42-E42 -> 420 | H42: 420 | I42: 420 | J42: 420 | K42: =I42-J42 -> 0
A43: 46069 | B43: LYS SARL - Redevance LYS TOWER 02/2026 | C43: 2026.01/SN/27 | D43: =+I43-E43 -> 400 | H43: 400 | I43: 400 | K43: =I43-J43 -> 400
A44: 46069 | B44: IMMEUBLE TATELIE - Redevance mensuelle 01/2026 - DECEMBRE ??? | C44: 2026.01/SN/28 | D44: =+I44-E44 -> 174 | H44: 157.5 | I44: 174 | J44: 174 | K44: =I44-J44 -> 0
...

Sheet Feuil1
