Workbook

Sheet 062026
A1: ELECTROCOOL
A2: RAPPORT DE CAISSE | L2: 46174
B3: LIBELLES | D3: USD | H3: EUROS | J3: Francs
C4: ENC CLIENT | D4: ENTREE ($) | E4: SORTIE ($) | F4: SOLDE ($) | G4: ENTREE (Euro) | H4: SORTIE (Euro) | I4: SOLDE (Euro) | J4: ENTREE (Francs) | K4: SORTIE (Francs) | L4: SOLDE (francs)
B5: REPORT | D5: ='052026'!F378 -> 982 | F5: =D5 -> 982 | G5: 0 | I5: 0 | J5: ='052026'!L378 -> 206690 | L5: =J5 -> 206690
F6: =+F5+C6+D6-E6 -> 982 | H6: 0 | I6: =I5++G6-H6 -> 0 | L6: =L5++J6-K6 -> 206690
F7: =+F6+C7+D7-E7 -> 982 | I7: =I6++G7-H7 -> 0 | L7: =L6++J7-K7 -> 206690
F8: =+F7+C8+D8-E8 -> 982 | I8: =I7++G8-H8 -> 0 | L8: =L7++J8-K8 -> 206690
F9: =+F8+C9+D9-E9 -> 982 | I9: =I8++G9-H9 -> 0 | L9: =L8++J9-K9 -> 206690
F10: =+F9+C10+D10-E10 -> 982 | I10: =I9++G10-H10 -> 0 | L10: =L9++J10-K10 -> 206690
F11: =+F10+C11+D11-E11 -> 982 | I11: =I10++G11-H11 -> 0 | L11: =L10++J11-K11 -> 206690
F12: =+F11+C12+D12-E12 -> 982 | I12: =I11++G12-H12 -> 0 | L12: =L11++J12-K12 -> 206690
F13: =+F12+C13+D13-E13 -> 982 | I13: =I12++G13-H13 -> 0 | L13: =L12++J13-K13 -> 206690
F14: =+F13+C14+D14-E14 -> 982 | I14: =I13++G14-H14 -> 0 | L14: =L13++J14-K14 -> 206690
F15: =+F14+C15+D15-E15 -> 982 | I15: =I14++G15-H15 -> 0 | L15: =L14++J15-K15 -> 206690
F16: =+F15+C16+D16-E16 -> 982 | I16: =I15++G16-H16 -> 0 | L16: =L15++J16-K16 -> 206690
F17: =+F16+C17+D17-E17 -> 982 | I17: =I16++G17-H17 -> 0 | L17: =L16++J17-K17 -> 206690
F18: =+F17+C18+D18-E18 -> 982 | I18: =I17++G18-H18 -> 0 | L18: =L17++J18-K18 -> 206690
... F28: =+F27+C28+D28-E28 -> 982 | I28: =I27++G28-H28 -> 0 | L28: =L27++J28-K28 -> 206690
F29: =+F28+C29+D29-E29 -> 982 | H29: 0 | I29: =I28++G29-H29 -> 0 | L29: =L28++J29-K29 -> 206690
F30: =+F29+C30+D30-E30 -> 982 | I30: =I29++G30-H30 -> 0 | L30: =L29++J30-K30 -> 206690
F31: =+F30+C31+D31-E31 -> 982 | I31: =I30++G31-H31 -> 0 | L31: =L30++J31-K31 -> 206690
F32: =+F31+C32+D32-E32 -> 982 | I32: =I31++G32-H32 -> 0 | L32: =L31++J32-K32 -> 206690
F33: =+F32+C33+D33-E33 -> 982 | I33: =I32++G33-H33 -> 0 | L33: =L32++J33-K33 -> 206690
F34: =+F33+C34+D34-E34 -> 982 | I34: =I33++G34-H34 -> 0 | L34: =L33++J34-K34 -> 206690
F35: =+F34+C35+D35-E35 -> 982 | I35: =I34++G35-H35 -> 0 | L35: =L34++J35-K35 -> 206690
F36: =+F35+C36+D36-E36 -> 982 | H36: 0 | I36: =I35++G36-H36 -> 0 | L36: =L35++J36-K36 -> 206690
F37: =+F36+C37+D37-E37 -> 982 | I37: =I36++G37-H37 -> 0 | L37: =L36++J37-K37 -> 206690
F38: =+F37+C38+D38-E38 -> 982 | I38: =I37++G38-H38 -> 0 | L38: =L37++J38-K38 -> 206690
F39: =+F38+C39+D39-E39 -> 982 | I39: =I38++G39-H39 -> 0 | L39: =L38++J39-K39 -> 206690
F40: =+F39+C40+D40-E40 -> 982 | H40: 0 | I40: =I39++G40-H40 -> 0 | L40: =L39++J40-K40 -> 206690
F41: =+F40+C41+D41-E41 -> 982 | I41: =I40++G41-H41 -> 0 | L41: =L40++J41-K41 -> 206690
F42: =+F41+C42+D42-E42 -> 982 | I42: =I41++G42-H42 -> 0 | L42: =L41++J42-K42 -> 206690
F43: =+F42+C43+D43-E43 -> 982 | I43: =I42++G43-H43 -> 0 | L43: =L42++J43-K43 -> 206690
F44: =+F43+C44+D44-E44 -> 982 | I44: =I43++G44-H44 -> 0 | L44: =L43++J44-K44 -> 206690
F45: =+F44+C45+D45-E45 -> 982 | I45: =I44++G45-H45 -> 0 | L45: =L44++J45-K45 -> 206690
F46: =+F45+C46+D46-E46 -> 982 | I46: =I45++G46-H46 -> 0 | L46: =L45++J46-K46 -> 206690
F47: =+F46+C47+D47-E47 -> 982 | H47: 0 | I47: =I46++G47-H47 -> 0 | L47: =L46++J47-K47 -> 206690
F48: =+F47+C48+D48-E48 -> 982 | I48: =I47++G48-H48 -> 0 | L48: =L47++J48-K48 -> 206690
F49: =+F48+C49+D49-E49 -> 982 | I49: =I48++G49-H49 -> 0 | L49: =L48++J49-K49 -> 206690
...

Sheet 052026
A1: ELECTROCOOL
A2: RAPPORT DE CAISSE | L2: 46143
B3: LIBELLES | D3: USD | H3: EUROS | J3: Francs
C4: ENC CLIENT | D4: ENTREE ($) | E4: SORTIE ($) | F4: SOLDE ($) | G4: ENTREE (Euro) | H4: SORTIE (Euro) | I4: SOLDE (Euro) | J4: ENTREE (Francs) | K4: SORTIE (Francs) | L4: SOLDE (francs)
B5: REPORT | D5: ='042026'!F331 -> 1184 | F5: =D5 -> 1184 | G5: 0 | I5: 0 | J5: 294216 | L5: =J5 -> 294216
A6: 46144 | B6: ALVARO - Evacuation poubelle NDOLO | F6: =+F5+C6+D6-E6 -> 1184 | H6: 0 | I6: =+I5+G6-H6 -> 0 | K6: 10000 | L6: =+L5+J6-K6 -> 284216
A7: 46146 | B7: DIDIER - Carburant TATA DELUXE | E7: 50 | F7: =+F6+C7+D7-E7 -> 1134 | H7: 0 | I7: =+I6+G7-H7 -> 0 | L7: =+L6+J7-K7 -> 284216
A8: 46146 | B8: LEKO - Carburant IST | E8: 40 | F8: =+F7+C8+D8-E8 -> 1094 | I8: =+I7+G8-H8 -> 0 | L8: =+L7+J8-K8 -> 284216
A9: 46146 | B9: CLAUDE - Carburant PICKUP L200 | E9: 50 | F9: =+F8+C9+D9-E9 -> 1044 | I9: =+I8+G9-H9 -> 0 | L9: =+L8+J9-K9 -> 284216
A10: 46146 | B10: PROSPERE - Carburant NISSAN/DG | E10: 70 | F10: =+F9+C10+D10-E10 -> 974 | I10: =+I9+G10-H10 -> 0 | L10: =+L9+J10-K10 -> 284216
A11: 46146 | B11: PROSPERE - Communications | E11: 10 | F11: =+F10+C11+D11-E11 -> 964 | I11: =+I10+G11-H11 -> 0 | L11: =+L10+J11-K11 -> 284216
A12: 46146 | B12: IMMEUBLE EBATA - Acpte Factures | C12: 20000 | F12: =+F11+C12+D12-E12 -> 20964 | I12: =+I11+G12-H12 -> 0 | L12: =+L11+J12-K12 -> 284216
A13: 46146 | B13: BAT CONGO - Acpte travaux encastrement & condensat | E13: 19000 | F13: =+F12+C13+D13-E13 -> 1964 | I13: =+I12+G13-H13 -> 0 | L13: =+L12+J13-K13 -> 284216
A14: 46146 | B14: MIESSI - Legalisation A.G.O. 2026/2025 | E14: 250 | F14: =+F13+C14+D14-E14 -> 1714 | I14: =+I13+G14-H14 -> 0 | L14: =+L13+J14-K14 -> 284216
A15: 46146 | B15: WAPETWA/MAMBINI/LUBAKI - Transport chantiers | F15: =+F14+C15+D15-E15 -> 1714 | I15: =+I14+G15-H15 -> 0 | K15: 15000 | L15: =+L14+J15-K15 -> 269216
A16: 46146 | B16: Emile KABASELE - IRL RESIDENCE IVAN | E16: 300 | F16: =+F15+C16+D16-E16 -> 1414 | I16: =+I15+G16-H16 -> 0 | L16: =+L15+J16-K16 -> 269216
A17: 46146 | B17: COMMUNICATIONS willy, georges, nancy, urbain | E17: 80 | F17: =+F16+C17+D17-E17 -> 1334 | I17: =+I16+G17-H17 -> 0 | L17: =+L16+J17-K17 -> 269216
A18: 46146 | B18: MNAOUER - Communications | E18: 20 | F18: =+F17+C18+D18-E18 -> 1314 | I18: =+I17+G18-H18 -> 0 | L18: =+L17+J18-K18 -> 269216
A19: 46146 | B19: COMMUNICATIONS franck, kusiekita, bangamo, ndona | E19: 40 | F19: =+F18+C19+D19-E19 -> 1274 | I19: =+I18+G19-H19 -> 0 | L19: =+L18+J19-K19 -> 269216
A20: 46146 | B20: BLAISE/DGM - Collation cfr visas volant (VERRVE-BOSSUT) | E20: 100 | F20: =+F19+C20+D20-E20 -> 1174 | I20: =+I19+G20-H20 -> 0 | L20: =+L19+J20-K20 -> 269216
A21: 46146 | B21: PRIMMO - 1 Bouteille azote | E21: 105 | F21: =+F20+C21+D21-E21 -> 1069 | I21: =+I20+G21-H21 -> 0 | L21: =+L20+J21-K21 -> 269216
A22: 46146 | B22: losembe 1 - Reparation fenetre cuisine BUREAU/NDOLO | F22: =+F21+C22+D22-E22 -> 1069 | I22: =+I21+G22-H22 -> 0 | K22: 20000 | L22: =+L21+J22-K22 -> 249216
A23: 46146 | B23: MNOUER - 1 SIM de pointage avec recharge | E23: 10 | F23: =+F22+C23+D23-E23 -> 1059 | I23: =+I22+G23-H23 -> 0 | L23: =+L22+J23-K23 -> 249216
A24: 46146 | B24: SHEHENAJ L.M. - Facture 2026.03/SN/66 | F24: =+F23+C24+D24-E24 -> 1059 | I24: =+I23+G24-H24 -> 0 | J24: 250500 | L24: =+L23+J24-K24 -> 499716
A25: 46147 | B25: EBCDC USD - RETRAIT | D25: 2000 | F25: =+F24+C25+D25-E25 -> 3059 | H25: 0 | I25: =+I24+G25-H25 -> 0 | L25: =+L24+J25-K25 -> 499716
A26: 46147 | B26: IY - APPRO CAISSE | D26: 9000 | F26: =+F25+C26+D26-E26 -> 12059 | I26: =+I25+G26-H26 -> 0 | L26: =+L25+J26-K26 -> 499716
A27: 46147 | B27: MBENKIE - Carburant groupe NDOLO | F27: =+F26+C27+D27-E27 -> 12059 | I27: =+I26+G27-H27 -> 0 | K27: 210000 | L27: =+L26+J27-K27 -> 289716
A28: 46147 | B28: MUPEPE - Solde honoraies comptables EX.2026/2025 | E28: 2500 | F28: =+F27+C28+D28-E28 -> 9559 | I28: =+I27+G28-H28 -> 0 | L28: =+L27+J28-K28 -> 289716
A29: 46147 | B29: MUTORO - Frais RAPPORT CONTRÔLE de 2024 à 2026 | E29: 2400 | F29: =+F28+C29+D29-E29 -> 7159 | I29: =+I28+G29-H29 -> 0 | L29: =+L28+J29-K29 -> 289716
A30: 46147 | B30: MNAOUER - Prestations 04/2026 | E30: 3000 | F30: =+F29+C30+D30-E30 -> 4159 | I30: =+I29+G30-H30 -> 0 | L30: =+L29+J30-K30 -> 289716
A31: 46147 | B31: MOATAZ - Communications 02-03/2026 | E31: 160 | F31: =+F30+C31+D31-E31 -> 3999 | I31: =+I30+G31-H31 -> 0 | L31: =+L30+J31-K31 -> 289716
A32: 46147 | B32: MOATAZ - Divers achats | E32: 299 | F32: =+F31+C32+D32-E32 -> 3700 | I32: =+I31+G32-H32 -> 0 | L32: =+L31+J32-K32 -> 289716
A33: 46147 | B33: KINKOLE - Frais maintenanciers HUB 04/2026 | E33: 500 | F33: =+F32+C33+D33-E33 -> 3200 | I33: =+I32+G33-H33 -> 0 | L33: =+L32+J33-K33 -> 289716
A34: 46147 | B34: ATRIUM - Accessoires divers cfr bon 3670 | E34: 1239 | F34: =+F33+C34+D34-E34 -> 1961 | I34: =+I33+G34-H34 -> 0 | L34: =+L33+J34-K34 -> 289716
A35: 46147 | B35: ATRIUM - 60Lg armaflex 32 | E35: 420 | F35: =+F34+C35+D35-E35 -> 1541 | I35: =+I34+G35-H35 -> 0 | L35: =+L34+J35-K35 -> 289716
A36: 46147 | B36: MAGASIN - 50Toiles iso, 5pqt baguette ag, 5gaz butane GF | E36: 225 | F36: =+F35+C36+D36-E36 -> 1316 | I36: =+I35+G36-H36 -> 0 | L36: =+L35+J36-K36 -> 289716
A37: 46147 | B37: MAGASIN - 10 Capas 50µf, 40&45µf, 35+5µf & 20 de 1,5µf | E37: 310 | F37: =+F36+C37+D37-E37 -> 1006 | I37: =+I36+G37-H37 -> 0 | L37: =+L36+J37-K37 -> 289716
A38: 46147 | B38: MAGASIN - 2 Crts savon liquide | E38: 60 | F38: =+F37+C38+D38-E38 -> 946 | I38: =+I37+G38-H38 -> 0 | L38: =+L37+J38-K38 -> 289716
A39: 46147 | B39: MAGASIN - 1Bouteille freon 410 & 1R22 | E39: 225 | F39: =+F38+C39+D39-E39 -> 721 | I39: =+I38+G39-H39 -> 0 | L39: =+L38+J39-K39 -> 289716
A40: 46147 | B40: MAGASIN - 1 Sac locks pour entretien | E40: 100 | F40: =+F39+C40+D40-E40 -> 621 | I40: =+I39+G40-H40 -> 0 | L40: =+L39+J40-K40 -> 289716
...

Sheet 042026
A1: ELECTROCOOL
A2: RAPPORT DE CAISSE | L2: 46113
B3: LIBELLES | D3: USD | H3: EUROS | J3: Francs
C4: ENC CLIENT | D4: ENTREE ($) | E4: SORTIE ($) | F4: SOLDE ($) | G4: ENTREE (Euro) | H4: SORTIE (Euro) | I4: SOLDE (Euro) | J4: ENTREE (Francs) | K4: SORTIE (Francs) | L4: SOLDE (francs)
B5: REPORT | D5: =+'032026'!F268 -> 9019 | F5: =D5 -> 9019 | G5: 0 | I5: 0 | J5: ='032026'!L268 -> 1081313 | L5: =J5 -> 1081313
A6: 46114 | B6: MBENKIE - Carburant groupe NDOLO | E6: 100 | F6: =+F5+C6+D6-E6 -> 8919 | H6: 0 | I6: =+I5+G6-H6 -> 0 | L6: =+L5+J6-K6 -> 1081313
A7: 46114 | B7: LEKO - Carburant IST | E7: 40 | F7: =+F6+C7+D7-E7 -> 8879 | I7: =+I6+G7-H7 -> 0 | L7: =+L6+J7-K7 -> 1081313
A8: 46114 | B8: KWAMI - Travaux local machine COMIMMO & acpte M.O. | E8: 824 | F8: =+F7+C8+D8-E8 -> 8055 | I8: =+I7+G8-H8 -> 0 | L8: =+L7+J8-K8 -> 1081313
A9: 46114 | B9: MAIEL - Prestations SUCRIERE 03/2026 | E9: 2250 | F9: =+F8+C9+D9-E9 -> 5805 | I9: =+I8+G9-H9 -> 0 | L9: =+L8+J9-K9 -> 1081313
A10: 46114 | B10: IY - Cotisation Famille YSEBOOT/Mariage NANCY | E10: 500 | F10: =+F9+C10+D10-E10 -> 5305 | I10: =+I9+G10-H10 -> 0 | L10: =+L9+J10-K10 -> 1081313
A11: 46114 | B11: COTISATION ELC / Mariage NANCY | E11: 100 | F11: =+F10+C11+D11-E11 -> 5205 | I11: =+I10+G11-H11 -> 0 | L11: =+L10+J11-K11 -> 1081313
A12: 46114 | B12: CHARLES - Reparation electrique MITHUBISHI&PATROL | E12: 50 | F12: =+F11+C12+D12-E12 -> 5155 | I12: =+I11+G12-H12 -> 0 | L12: =+L11+J12-K12 -> 1081313
A13: 46114 | B13: PGHK - 1 Tenue complet, chaussure+decoration NDAKUZU | E13: 70 | F13: =+F12+C13+D13-E13 -> 5085 | I13: =+I12+G13-H13 -> 0 | L13: =+L12+J13-K13 -> 1081313
A14: 46114 | B14: PRIMMO - 2 Bouteilles azote, 1 acetylene, 1 oxygene | E14: 406 | F14: =+F13+C14+D14-E14 -> 4679 | I14: =+I13+G14-H14 -> 0 | L14: =+L13+J14-K14 -> 1081313
A15: 46114 | B15: PRIMMO - 100m cable 4x2,5mm² & 10 lames scie | E15: 265 | F15: =+F14+C15+D15-E15 -> 4414 | I15: =+I14+G15-H15 -> 0 | L15: =+L14+J15-K15 -> 1081313
A16: 46114 | B16: MANGA FLORE - Desinsectisation jardin 12/2025 | E16: 134 | F16: =+F15+C16+D16-E16 -> 4280 | I16: =+I15+G16-H16 -> 0 | L16: =+L15+J16-K16 -> 1081313
A17: 46114 | B17: MAMBA SECURITY - Facture NDOLO&RESIDENCE 01/2026 | E17: 750 | F17: =+F16+C17+D17-E17 -> 3530 | I17: =+I16+G17-H17 -> 0 | L17: =+L16+J17-K17 -> 1081313
A18: 46114 | B18: KIABA JEAN - Prêt société | E18: 500 | F18: =+F17+C18+D18-E18 -> 3030 | I18: =+I17+G18-H18 -> 0 | L18: =+L17+J18-K18 -> 1081313
... A20: 46114 | B20: MUPEPE - Divers ONEC | E20: 2000 | F20: =+F19+C20+D20-E20 -> 780 | I20: =+I19+G20-H20 -> 0 | L20: =+L19+J20-K20 -> 1081313
A21: 46114 | B21: GEORGES - RETOUR CAISSE | F21: =+F20+C21+D21-E21 -> 780 | I21: =+I20+G21-H21 -> 0 | J21: 22500 | L21: =+L20+J21-K21 -> 1103813
A22: 46114 | B22: DIDIER - 1L huile frein, 2L huile hydrau, 10L moteur STOCK | F22: =+F21+C22+D22-E22 -> 780 | I22: =+I21+G22-H22 -> 0 | K22: 203500 | L22: =+L21+J22-K22 -> 900313
F23: =+F22+C23+D23-E23 -> 780 | I23: =I22++G23-H23 -> 0 | L23: =L22++J23-K23 -> 900313
A24: 46115 | B24: LOSEMBE1&DIDIER - Transport PRIMMO | F24: =+F23+C24+D24-E24 -> 780 | H24: 0 | I24: =+I23+G24-H24 -> 0 | K24: 20000 | L24: =+L23+J24-K24 -> 880313
A25: 46115 | B25: Serge KABULO - TRFT MPESA/ Prestations 03/2026 | E25: 250 | F25: =+F24+C25+D25-E25 -> 530 | I25: =+I24+G25-H25 -> 0 | L25: =+L24+J25-K25 -> 880313
A26: 46115 | B26: UTEXAFRICA - 30Disques c230, 1bte antirouille, thinner--- | E26: 45 | F26: =+F25+C26+D26-E26 -> 485 | I26: =+I25+G26-H26 -> 0 | L26: =+L25+J26-K26 -> 880313
A27: 46115 | B27: PGHK - 1crt colle contact, 100chevilles+vis--- | E27: 135 | F27: =+F26+C27+D27-E27 -> 350 | I27: =+I26+G27-H27 -> 0 | L27: =+L26+J27-K27 -> 880313
A28: 46115 | B28: ETS NEW CEPRONAC - Passage immondices RESIDENCE IY | E28: 125 | F28: =+F27+C28+D28-E28 -> 225 | I28: =+I27+G28-H28 -> 0 | L28: =+L27+J28-K28 -> 880313
A29: 46115 | B29: ALVARO - Evacuation poubelle NDOLO | F29: =+F28+C29+D29-E29 -> 225 | I29: =+I28+G29-H29 -> 0 | K29: 10000 | L29: =+L28+J29-K29 -> 870313
A30: 46115 | B30: LYS HEAVEN - 1Rlx flexible 50 | E30: 125 | F30: =+F29+C30+D30-E30 -> 100 | I30: =+I29+G30-H30 -> 0 | L30: =+L29+J30-K30 -> 870313
A31: 46115 | B31: UTEX/SILIKIN - 1 Bte colle tangit 500gr | E31: 15 | F31: =+F30+C31+D31-E31 -> 85 | I31: =+I30+G31-H31 -> 0 | L31: =+L30+J31-K31 -> 870313
F32: =+F31+C32+D32-E32 -> 85 | I32: =I31++G32-H32 -> 0 | L32: =L31++J32-K32 -> 870313
A33: 46119 | B33: TMB USD - RETRAIT | D33: 1500 | F33: =+F32+C33+D33-E33 -> 1585 | H33: 0 | I33: =+I32+G33-H33 -> 0 | L33: =+L32+J33-K33 -> 870313
A34: 46119 | B34: IMMEUBLE MARIE YVETTE - Redevance 02/2026 | C34: 183 | F34: =+F33+C34+D34-E34 -> 1768 | I34: =+I33+G34-H34 -> 0 | L34: =+L33+J34-K34 -> 870313
A35: 46119 | B35: LOSEMBE 1 - Transport / Reparation flexible NACELLE | F35: =+F34+C35+D35-E35 -> 1768 | I35: =+I34+G35-H35 -> 0 | K35: 10000 | L35: =+L34+J35-K35 -> 860313
A36: 46119 | B36: IY - Appro caisse | D36: 100 | F36: =+F35+C36+D36-E36 -> 1868 | I36: =+I35+G36-H36 -> 0 | L36: =+L35+J36-K36 -> 860313
A37: 46119 | B37: DG - Appro caisse | D37: 100 | F37: =+F36+C37+D37-E37 -> 1968 | I37: =+I36+G37-H37 -> 0 | L37: =+L36+J37-K37 -> 860313
A38: 46119 | B38: JETONS DE PRESENCE CDT/WILLY | E38: 200 | F38: =+F37+C38+D38-E38 -> 1768 | I38: =+I37+G38-H38 -> 0 | L38: =+L37+J38-K38 -> 860313
A39: 46119 | B39: DIDIER - Course de service | F39: =+F38+C39+D39-E39 -> 1768 | I39: =+I38+G39-H39 -> 0 | K39: 10000 | L39: =+L38+J39-K39 -> 850313
A40: 46119 | B40: DIDIER - Carburant TATA DELUXE | E40: 50 | F40: =+F39+C40+D40-E40 -> 1718 | I40: =+I39+G40-H40 -> 0 | L40: =+L39+J40-K40 -> 850313
A41: 46119 | B41: MALEWU Pirins - Prestations 13 jours | F41: =+F40+C41+D41-E41 -> 1718 | I41: =+I40+G41-H41 -> 0 | K41: 372604 | L41: =+L40+J41-K41 -> 477709
...

Sheet 032026
A1: ELECTROCOOL
A2: RAPPORT DE CAISSE | L2: 46082
B3: LIBELLES | D3: USD | H3: EUROS | J3: Francs
C4: ENC CLIENT | D4: ENTREE ($) | E4: SORTIE ($) | F4: SOLDE ($) | G4: ENTREE (Euro) | H4: SORTIE (Euro) | I4: SOLDE (Euro) | J4: ENTREE (Francs) | K4: SORTIE (Francs) | L4: SOLDE (francs)
B5: REPORT | D5: 47 | F5: =D5 -> 47 | G5: 0 | I5: 0 | J5: 87187 | L5: =J5 -> 87187
A6: 46083 | B6: RAWBANK USD - RETRAIT | D6: 2000 | F6: =+F5+C6+D6-E6 -> 2047 | H6: 0 | I6: =+I5+G6-H6 -> 0 | L6: =+L5+J6-K6 -> 87187
A7: 46083 | B7: MUMBIMBI - Reparation pneu NISSAN PATROL | F7: =+F6+C7+D7-E7 -> 2047 | I7: =+I6+G7-H7 -> 0 | K7: 20000 | L7: =+L6+J7-K7 -> 67187
A8: 46083 | B8: MUMBIMBI - Reparation pneu JAC/CONTAINER | F8: =+F7+C8+D8-E8 -> 2047 | I8: =+I7+G8-H8 -> 0 | K8: 10000 | L8: =+L7+J8-K8 -> 57187
A9: 46083 | B9: RESIDENCE IVAN - M.O. Reparation toiture | E9: 50 | F9: =+F8+C9+D9-E9 -> 1997 | I9: =+I8+G9-H9 -> 0 | L9: =+L8+J9-K9 -> 57187
A10: 46083 | B10: COMMUNICATIONS willy, georges, urbain, nancy | E10: 80 | F10: =+F9+C10+D10-E10 -> 1917 | I10: =+I9+G10-H10 -> 0 | L10: =+L9+J10-K10 -> 57187
A11: 46083 | B11: MNAOUER - Communications | E11: 20 | F11: =+F10+C11+D11-E11 -> 1897 | I11: =+I10+G11-H11 -> 0 | L11: =+L10+J11-K11 -> 57187
A12: 46083 | B12: COMMUNICATIONS franck, kusiekita, bangamo, ndona | E12: 40 | F12: =+F11+C12+D12-E12 -> 1857 | I12: =+I11+G12-H12 -> 0 | L12: =+L11+J12-K12 -> 57187
A13: 46083 | B13: Immeuble IMANI - Facture 2026.01/DA/58 | C13: 243 | F13: =+F12+C13+D13-E13 -> 2100 | I13: =+I12+G13-H13 -> 0 | L13: =+L12+J13-K13 -> 57187
A14: 46083 | B14: CHANGE | E14: 50 | F14: =+F13+C14+D14-E14 -> 2050 | I14: =+I13+G14-H14 -> 0 | J14: 112500 | L14: =+L13+J14-K14 -> 169687
A15: 46083 | B15: KINKOLE - Frais maintenanciers+supplement transport | E15: 500 | F15: =+F14+C15+D15-E15 -> 1550 | I15: =+I14+G15-H15 -> 0 | K15: 150000 | L15: =+L14+J15-K15 -> 19687
A16: 46084 | B16: MALEWU - Carburant TATA/DELUXE | E16: 50 | F16: =+F15+C16+D16-E16 -> 1500 | H16: 0 | I16: =+I15+G16-H16 -> 0 | L16: =+L15+J16-K16 -> 19687
A17: 46084 | B17: MBENKIE - Carburant JAC/CONTAINER | E17: 50 | F17: =+F16+C17+D17-E17 -> 1450 | I17: =+I16+G17-H17 -> 0 | L17: =+L16+J17-K17 -> 19687
A18: 46084 | B18: UTEX - 18 Piles touches cfr GEORGES | F18: =+F17+C18+D18-E18 -> 1450 | I18: =+I17+G18-H18 -> 0 | K18: 20000 | L18: =+L17+J18-K18 -> -313
A19: 46084 | B19: PROSPERE LIHOZA - Carburant NISSAN / DG | E19: 70 | F19: =+F18+C19+D19-E19 -> 1380 | I19: =+I18+G19-H19 -> 0 | L19: =+L18+J19-K19 -> -313
A20: 46084 | B20: PROSPERE LIHOZA - Communications | E20: 10 | F20: =+F19+C20+D20-E20 -> 1370 | I20: =+I19+G20-H20 -> 0 | L20: =+L19+J20-K20 -> -313
A21: 46084 | B21: CLAUDE - Carburant PICKUP L200 | E21: 50 | F21: =+F20+C21+D21-E21 -> 1320 | I21: =+I20+G21-H21 -> 0 | L21: =+L20+J21-K21 -> -313
A22: 46084 | B22: LOSEMBE 1 - Carburant groupe NDOLO | E22: 100 | F22: =+F21+C22+D22-E22 -> 1220 | I22: =+I21+G22-H22 -> 0 | L22: =+L21+J22-K22 -> -313
A23: 46084 | B23: CHICK - Carburant PRADO/DG | E23: 70 | F23: =+F22+C23+D23-E23 -> 1150 | I23: =+I22+G23-H23 -> 0 | L23: =+L22+J23-K23 -> -313
A24: 46084 | B24: Poupon IKELE - Bache bateau IY | E24: 320 | F24: =+F23+C24+D24-E24 -> 830 | I24: =+I23+G24-H24 -> 0 | L24: =+L23+J24-K24 -> -313
A25: 46084 | B25: MAJESTIC - 1 Bouteille freon R404 | E25: 140 | F25: =+F24+C25+D25-E25 -> 690 | I25: =+I24+G25-H25 -> 0 | L25: =+L24+J25-K25 -> -313
A26: 46084 | B26: PRIMMO - 5 Crts colle contact | E26: 300 | F26: =+F25+C26+D26-E26 -> 390 | I26: =+I25+G26-H26 -> 0 | L26: =+L25+J26-K26 -> -313
A27: 46084 | B27: ATRIUM - Crts colle contact | E27: 300 | F27: =+F26+C27+D27-E27 -> 90 | I27: =+I26+G27-H27 -> 0 | L27: =+L26+J27-K27 -> -313
A28: 46084 | B28: LIOKO - Transport MONKOLE | F28: =+F27+C28+D28-E28 -> 90 | I28: =+I27+G28-H28 -> 0 | K28: 12000 | L28: =+L27+J28-K28 -> -12313
A29: 46084 | B29: GEORGES - 1 Chambre à air NISSAN PATROL | E29: 10 | F29: =+F28+C29+D29-E29 -> 80 | I29: =+I28+G29-H29 -> 0 | L29: =+L28+J29-K29 -> -12313
A30: 46084 | B30: CHANGE | E30: 50 | F30: =+F29+C30+D30-E30 -> 30 | I30: =+I29+G30-H30 -> 0 | J30: 112500 | L30: =+L29+J30-K30 -> 100187
A31: 46084 | B31: ATRIUM - Evacuation poubelle 4e Etage | F31: =+F30+C31+D31-E31 -> 30 | I31: =+I30+G31-H31 -> 0 | K31: 20000 | L31: =+L30+J31-K31 -> 80187
A32: 46084 | B32: DEV GROUP-Fact.2025/SN/129-149-164-174 & 2026.01/SN/12 | C32: 1114 | F32: =+F31+C32+D32-E32 -> 1144 | I32: =+I31+G32-H32 -> 0 | L32: =+L31+J32-K32 -> 80187
A33: 46085 | B33: LOSEMBE 1 - Transport RESIDENCE IVAN | F33: =+F32+C33+D33-E33 -> 1144 | H33: 0 | I33: =+I32+G33-H33 -> 0 | K33: 10000 | L33: =+L32+J33-K33 -> 70187
A34: 46085 | B34: PRIMMO - 5Pqts electrodes 2,25 & 10pqts baguettes ag | E34: 235 | F34: =+F33+C34+D34-E34 -> 909 | I34: =+I33+G34-H34 -> 0 | L34: =+L33+J34-K34 -> 70187
A35: 46085 | B35: ATRIUM - 3L miel & 1bte lait | E35: 74 | F35: =+F34+C35+D35-E35 -> 835 | I35: =+I34+G35-H35 -> 0 | L35: =+L34+J35-K35 -> 70187
A36: 46085 | B36: PRIMMO - 3L miel & 1 bte lait | E36: 74 | F36: =+F35+C36+D36-E36 -> 761 | I36: =+I35+G36-H36 -> 0 | L36: =+L35+J36-K36 -> 70187
A37: 46085 | B37: COMIMMO 2 - 2 Bouteille acetylene, 2 oxygene | E37: 392 | F37: =+F36+C37+D37-E37 -> 369 | I37: =+I36+G37-H37 -> 0 | L37: =+L36+J37-K37 -> 70187
A38: 46085 | B38: LOSEMBE 1 - Entretien groupe NDOLO | E38: 120 | F38: =+F37+C38+D38-E38 -> 249 | I38: =+I37+G38-H38 -> 0 | L38: =+L37+J38-K38 -> 70187
A39: 46085 | B39: LOSEMBE 1 - Eclairage entrepot NDOLO | E39: 70 | F39: =+F38+C39+D39-E39 -> 179 | I39: =+I38+G39-H39 -> 0 | L39: =+L38+J39-K39 -> 70187
A40: 46085 | B40: COMIMMO 2 - Acpte Facture 2025/DA/114 | C40: 9500 | F40: =+F39+C40+D40-E40 -> 9679 | I40: =+I39+G40-H40 -> 0 | L40: =+L39+J40-K40 -> 70187
...

Sheet 022026
A1: ELECTROCOOL
A2: JOURNAL MENSUEL DE CAISSE | L2: 46054
B3: LIBELLES | D3: USD | H3: EUROS | J3: Francs
C4: ENC CLIENT | D4: ENTREE ($) | E4: SORTIE ($) | F4: SOLDE ($) | G4: ENTREE (Euro) | H4: SORTIE (Euro) | I4: SOLDE (Euro) | J4: ENTREE (Francs) | K4: SORTIE (Francs) | L4: SOLDE (francs)
B5: REPORT | D5: 662 | F5: =D5 -> 662 | G5: 0 | I5: 0 | J5: 26967 | L5: =J5 -> 26967
A6: 46055 | B6: RAWBANK USD - RETRAIT | D6: 1500 | F6: =+F5+C6+D6-E6 -> 2162 | H6: 0 | I6: =+I5+G6-H6 -> 0 | L6: =+L5+J6-K6 -> 26967
A7: 46055 | B7: CLAUDE - Carburant PICKUP L200 | E7: 50 | F7: =+F6+C7+D7-E7 -> 2112 | I7: =+I6+G7-H7 -> 0 | L7: =+L6+J7-K7 -> 26967
A8: 46055 | B8: PROSPERE - Carburant NISSAN/DG | E8: 70 | F8: =+F7+C8+D8-E8 -> 2042 | I8: =+I7+G8-H8 -> 0 | L8: =+L7+J8-K8 -> 26967
A9: 46055 | B9: PROSPERE - Communications | E9: 10 | F9: =+F8+C9+D9-E9 -> 2032 | I9: =+I8+G9-H9 -> 0 | L9: =+L8+J9-K9 -> 26967
A10: 46055 | B10: MBENKIE - Carburant JAC/CONTAINER | E10: 50 | F10: =+F9+C10+D10-E10 -> 1982 | I10: =+I9+G10-H10 -> 0 | L10: =+L9+J10-K10 -> 26967
A11: 46055 | B11: CHICK - Carburant PRADO | E11: 70 | F11: =+F10+C11+D11-E11 -> 1912 | I11: =+I10+G11-H11 -> 0 | L11: =+L10+J11-K11 -> 26967
A12: 46055 | B12: LOSEMBE 1 - Carburant groupe NDOLO | E12: 100 | F12: =+F11+C12+D12-E12 -> 1812 | I12: =+I11+G12-H12 -> 0 | L12: =+L11+J12-K12 -> 26967
A13: 46055 | B13: KINKOLE - 4 Rlmnts 6201 | E13: 50 | F13: =+F12+C13+D13-E13 -> 1762 | I13: =+I12+G13-H13 -> 0 | L13: =+L12+J13-K13 -> 26967
A14: 46055 | B14: PRIMMO - Journaliers dechargement container 4 | E14: 100 | F14: =+F13+C14+D14-E14 -> 1662 | I14: =+I13+G14-H14 -> 0 | L14: =+L13+J14-K14 -> 26967
A15: 46055 | B15: COMMUNICATIONS willy, georges, urbain, nancy | E15: 80 | F15: =+F14+C15+D15-E15 -> 1582 | I15: =+I14+G15-H15 -> 0 | L15: =+L14+J15-K15 -> 26967
A16: 46055 | B16: COMMUNCATIONS franck, kusiekita, bangamo | E16: 30 | F16: =+F15+C16+D16-E16 -> 1552 | I16: =+I15+G16-H16 -> 0 | L16: =+L15+J16-K16 -> 26967
A17: 46055 | B17: MNAOUER - Communications | E17: 20 | F17: =+F16+C17+D17-E17 -> 1532 | I17: =+I16+G17-H17 -> 0 | L17: =+L16+J17-K17 -> 26967
A18: 46055 | B18: LUBAKI - Avance pension de retraite | E18: 500 | F18: =+F17+C18+D18-E18 -> 1032 | I18: =+I17+G18-H18 -> 0 | L18: =+L17+J18-K18 -> 26967
... A20: 46055 | B20: ATRIUM - Impression 6plans A0 | E20: 90 | F20: =+F19+C20+D20-E20 -> 742 | I20: =+I19+G20-H20 -> 0 | L20: =+L19+J20-K20 -> 26967
A21: 46056 | B21: RAWBANK USD - RETRAIT | D21: 2000 | F21: =+F20+C21+D21-E21 -> 2742 | H21: 0 | I21: =+I20+G21-H21 -> 0 | L21: =+L20+J21-K21 -> 26967
A22: 46056 | B22: SOFIBANK USD - RETRAIT | D22: 2000 | F22: =+F21+C22+D22-E22 -> 4742 | I22: =+I21+G22-H22 -> 0 | L22: =+L21+J22-K22 -> 26967
A23: 46056 | B23: RESIDENCE IVAN - IF & IRL 4eTRIM.2025+Frais Mpesa | E23: 900 | F23: =+F22+C23+D23-E23 -> 3842 | I23: =+I22+G23-H23 -> 0 | K23: 10000 | L23: =+L22+J23-K23 -> 16967
A24: 46056 | B24: VENUS/MERVEILLE - 20Baguettes, 3gaz butane, 3disques D | E24: 220 | F24: =+F23+C24+D24-E24 -> 3622 | I24: =+I23+G24-H24 -> 0 | L24: =+L23+J24-K24 -> 16967
A25: 46056 | B25: KINKOLE - Frais journaliers entretien CF/HUB | E25: 120 | F25: =+F24+C25+D25-E25 -> 3502 | I25: =+I24+G25-H25 -> 0 | L25: =+L24+J25-K25 -> 16967
A26: 46056 | B26: ATRIUM - 10Tenues completes | E26: 350 | F26: =+F25+C26+D26-E26 -> 3152 | I26: =+I25+G26-H26 -> 0 | L26: =+L25+J26-K26 -> 16967
A27: 46056 | B27: PRIMMO - Accessoires divers cfr bon 3119 | E27: 900 | F27: =+F26+C27+D27-E27 -> 2252 | I27: =+I26+G27-H27 -> 0 | L27: =+L26+J27-K27 -> 16967
A28: 46056 | B28: ATRIUM - Divers outillage cfr bon 3002 | E28: 1100 | F28: =+F27+C28+D28-E28 -> 1152 | I28: =+I27+G28-H28 -> 0 | L28: =+L27+J28-K28 -> 16967
A29: 46056 | B29: MAGASIN - 2Pqts pinceaux pour entretien | E29: 30 | F29: =+F28+C29+D29-E29 -> 1122 | I29: =+I28+G29-H29 -> 0 | L29: =+L28+J29-K29 -> 16967
A30: 46056 | B30: MAGASIN - 1Ballon de lock entretien | E30: 100 | F30: =+F29+C30+D30-E30 -> 1022 | I30: =+I29+G30-H30 -> 0 | L30: =+L29+J30-K30 -> 16967
A31: 46056 | B31: MAGASIN - 10 Supports condenseurs | E31: 150 | F31: =+F30+C31+D31-E31 -> 872 | I31: =+I30+G31-H31 -> 0 | L31: =+L30+J31-K31 -> 16967
A32: 46056 | B32: MAGASIN - 50 Capas 1,5µf | E32: 100 | F32: =+F31+C32+D32-E32 -> 772 | I32: =+I31+G32-H32 -> 0 | L32: =+L31+J32-K32 -> 16967
A33: 46056 | B33: DIVERS | E33: 100 | F33: =+F32+C33+D33-E33 -> 672 | I33: =+I32+G33-H33 -> 0 | L33: =+L32+J33-K33 -> 16967
A34: 46057 | B34: RAWBANK USD - RETRAIT | D34: 1500 | F34: =+F33+C34+D34-E34 -> 2172 | H34: 0 | I34: =+I33+G34-H34 -> 0 | L34: =+L33+J34-K34 -> 16967
A35: 46057 | B35: SOFIBANK USD - RETRAIT | D35: 2500 | F35: =+F34+C35+D35-E35 -> 4672 | I35: =+I34+G35-H35 -> 0 | L35: =+L34+J35-K35 -> 16967
A36: 46057 | B36: MOATAZ - Prestations 01/2026 | E36: 2250 | F36: =+F35+C36+D36-E36 -> 2422 | I36: =+I35+G36-H36 -> 0 | K36: 10000 | L36: =+L35+J36-K36 -> 6967
A37: 46057 | B37: CHICK - Communications | E37: 10 | F37: =+F36+C37+D37-E37 -> 2412 | I37: =+I36+G37-H37 -> 0 | L37: =+L36+J37-K37 -> 6967
A38: 46057 | B38: DIDIER - Achat siliconne IST | F38: =+F37+C38+D38-E38 -> 2412 | I38: =+I37+G38-H38 -> 0 | K38: 5000 | L38: =+L37+J38-K38 -> 1967
A39: 46057 | B39: SUCRIERE - Accessoires divers cfr bon 3132 | E39: 635 | F39: =+F38+C39+D39-E39 -> 1777 | I39: =+I38+G39-H39 -> 0 | L39: =+L38+J39-K39 -> 1967
A40: 46057 | B40: PRIMMO - 2 Bouteilles freon azote, 2 acetylene, 2 oxygene | E40: 632 | F40: =+F39+C40+D40-E40 -> 1145 | I40: =+I39+G40-H40 -> 0 | L40: =+L39+J40-K40 -> 1967
A41: 46057 | B41: CHANGE | E41: 100 | F41: =+F40+C41+D41-E41 -> 1045 | I41: =+I40+G41-H41 -> 0 | J41: 220000 | L41: =+L40+J41-K41 -> 221967
...

Sheet 012026
A1: ELECTROCOOL
A2: RAPPORT DE CAISSE | L2: 46023
B3: LIBELLES | D3: USD | H3: EUROS | J3: Francs
C4: ENC CLIENT | D4: ENTREE ($) | E4: SORTIE ($) | F4: SOLDE ($) | G4: ENTREE (Euro) | H4: SORTIE (Euro) | I4: SOLDE (Euro) | J4: ENTREE (Francs) | K4: SORTIE (Francs) | L4: SOLDE (francs)
B5: REPORT | D5: 40 | F5: =+D5 -> 40 | G5: 0 | I5: 0 | J5: 148014 | L5: 148014
A6: 46024 | B6: RAWBANK USD - RETRAIT | D6: 4500 | F6: =+F5+C6+D6-E6 -> 4540 | H6: 0 | I6: 0 | L6: 148014
A7: 46024 | B7: RESIDENCE IVAN - Paie agents 12/2025 | E7: 420 | F7: =+F6+C7+D7-E7 -> 4120 | I7: 0 | L7: 148014
A8: 46024 | B8: RESIDENCE DG - Paie agents 12/2025 | E8: 450 | F8: =+F7+C8+D8-E8 -> 3670 | I8: 0 | L8: 148014
A9: 46024 | B9: EGSC - SOLDE PRIME agents 12/2025 | E9: 2100 | F9: =+F8+C9+D9-E9 -> 1570 | I9: 0 | L9: 148014
A10: 46024 | B10: WILLY - Prime 2025 | E10: 900 | F10: =+F9+C10+D10-E10 -> 670 | I10: 0 | L10: 148014
A11: 46024 | B11: WILLY - (Frais funeraires) | E11: 600 | F11: =+F10+C11+D11-E11 -> 70 | I11: 0 | L11: 148014
A12: 46024 | B12: SERGE - TRFT / LUSHI + Frais | E12: 150 | F12: =+F11+C12+D12-E12 -> -80 | I12: 0 | K12: 10000 | L12: 138014
A13: 46024 | B13: RAWBANK USD - RETRAIT | D13: 1500 | F13: =+F12+C13+D13-E13 -> 1420 | I13: 0 | L13: 138014
A14: 46024 | B14: CHANGE | E14: 850 | F14: =+F13+C14+D14-E14 -> 570 | I14: 0 | J14: 1870000 | L14: 2008014
A15: 46024 | B15: CDT - Cotisation syndicale s/Gratification ELECTROCOOL | F15: =+F14+C15+D15-E15 -> 570 | I15: 0 | K15: 410000 | L15: 1598014
A16: 46024 | B16: DIDIER - Rechanges NISSAN DG | F16: =+F15+C16+D16-E16 -> 570 | I16: 0 | K16: 1449000 | L16: 149014
A17: 46024 | B17: MBUTELA Brandon - complement prime 12/2025 | E17: 50 | F17: =+F16+C17+D17-E17 -> 520 | I17: 0 | L17: 149014
A18: 46024 | B18: ATRIUM - 10 Disques c125 | F18: =+F17+C18+D18-E18 -> 520 | I18: 0 | K18: 19800 | L18: 129214
A19: 46024 | B19: FRANCK - Location Véhicule / Transport container colis | E19: 200 | F19: =+F18+C19+D19-E19 -> 320 | I19: 0 | L19: 129214
A20: 46024 | B20: FRANCK - Frais journaliers colis/ CONTAINER | E20: 100 | F20: =+F19+C20+D20-E20 -> 220 | I20: 0 | L20: 129214
A21: 46024 | B21: FRANCK - Transport chauffeurs DIDIER&MBENKIE | F21: =+F20+C21+D21-E21 -> 220 | I21: 0 | K21: 50000 | L21: 79214
A22: 46024 | B22: BENI - Travaux peinture RESIDENCE DG | E22: 55 | F22: =+F21+C22+D22-E22 -> 165 | I22: 0 | L22: 79214
A23: 46024 | B23: RESIDENCE DG - 1 Relais compact 20A cfr GEIRGES | E23: 25 | F23: =+F22+C23+D23-E23 -> 140 | I23: 0 | L23: 79214
A24: 46025 | B24: PGHK - 1Lg flexible non isolé 100 (RETOUR/NON PAYE) | D24: 25 | F24: =+F23+D24-E24 -> 165 | I24: 0 | L24: =+L23+J24-K24 -> 79214
A25: 46025 | B25: LYS CENTER - 1 Bouteille freon 410 (RETOUR/NON PAYE) | D25: 140 | F25: =+F24+D25-E25 -> 305 | I25: 0 | L25: =+L24+J25-K25 -> 79214
A26: 46025 | B26: ALBERT - Carburant NISSAN/DG-PRADO-NISSAN PATROL | E26: 150 | F26: =+F25+D26-E26 -> 155 | I26: 0 | L26: =+L25+J26-K26 -> 79214
A27: 46025 | B27: CDT - Cotisation syndicale s/Gratification ELECTROCOOL | D27: 182 | F27: =+F26+D27-E27 -> 337 | I27: 0 | L27: =+L26+J27-K27 -> 79214
A28: 46025 | B28: ATRIUM - 10 Disques c125 (19800fc) | D28: 9 | F28: =+F27+D28-E28 -> 346 | I28: 0 | L28: =+L27+J28-K28 -> 79214
A29: 46028 | B29: EBCDC USD - RETRAIT | D29: 3000 | F29: =+F28+D29-E29 -> 3346 | H29: 0 | I29: 0 | L29: =+L28+J29-K29 -> 79214
A30: 46025 | B30: DIDIER - Frais electricien ANCIEN JAC | E30: 150 | F30: =+F29+D30-E30 -> 3196 | H30: 0 | I30: 0 | L30: =+L29+J30-K30 -> 79214
A31: 46025 | B31: ALBERT - Frais aero, protocole, parking, bagages | E31: 60 | F31: =+F30+D31-E31 -> 3136 | I31: 0 | L31: =+L30+J31-K31 -> 79214
A32: 46028 | B32: CHICK - Achat eau DG&BUREAU | E32: 20 | F32: =+F31+D32-E32 -> 3116 | I32: 0 | L32: =+L31+J32-K32 -> 79214
A33: 46028 | B33: CLAUDE - Carburant PICKUP L200 | E33: 50 | F33: =+F32+D33-E33 -> 3066 | I33: 0 | L33: =+L32+J33-K33 -> 79214
A34: 46028 | B34: COMMUNICATIONS willy, georges, urbain | E34: 60 | F34: =+F33+D34-E34 -> 3006 | I34: 0 | L34: =+L33+J34-K34 -> 79214
A35: 46028 | B35: HANS - Communications | E35: 20 | F35: =+F34+D35-E35 -> 2986 | I35: 0 | L35: =+L34+J35-K35 -> 79214
A36: 46028 | B36: COMMUNICATIONS franck, kusiekita, bangamo | E36: 30 | F36: =+F35+D36-E36 -> 2956 | I36: 0 | L36: =+L35+J36-K36 -> 79214
A37: 46028 | B37: NDONA - Communications | E37: 10 | F37: =+F36+D37-E37 -> 2946 | I37: 0 | L37: =+L36+J37-K37 -> 79214
A38: 46028 | B38: RESIDENCE IVAN - Electricité prepaid | E38: 100 | F38: =+F37+D38-E38 -> 2846 | I38: 0 | L38: =+L37+J38-K38 -> 79214
A39: 46028 | B39: PGHK - 1Lg flexible non isolé 100 | E39: 25 | F39: =+F38+D39-E39 -> 2821 | I39: 0 | L39: =+L38+J39-K39 -> 79214
A40: 46028 | B40: LYS CENTER - 1 Bouteille freon 410 | E40: 140 | F40: =+F39+D40-E40 -> 2681 | I40: 0 | L40: =+L39+J40-K40 -> 79214
...
